Workbook

Sheet POL
A1: POL.Weiyun | B1: POL.Fleet | C1: Repeat | D1: RANGE | E1: SUB RANGE | F1: Port Code | G1: st | H1: rg | I1: 001 | J1: 365
A2: DALIAN(大连) | B2: Dalian, China | C2: DALIAN(大连) | D2: East Asia | E2: North China / Korea / Bohai Bay | F2: CNDLC | G2: ngJ9pZF1dUQkTJV1KSwmlw%253D%253D | H2: ngJ9pZF1dUQkTJV1KSwmlw%253D%253D | I2: =COUNTIF('Port Optimization 001'!C:C,表3[[#This Row],[Port Code]]) -> 32 | J2: =COUNTIF('Port Optimization 365'!C:C,表3[[#This Row],[Port Code]]) -> 32
A3: TIANJIN(天津) | B3: Xingang, China | C3: TIANJIN(天津) | D3: East Asia | E3: North China / Korea / Bohai Bay | F3: CNTXG | G3: 9vlbrGDCGWoPotdwnakh4g%253D%253D | H3: 9vlbrGDCGWoPotdwnakh4g%253D%253D | I3: =COUNTIF('Port Optimization 001'!C:C,表3[[#This Row],[Port Code]]) -> 45 | J3: =COUNTIF('Port Optimization 365'!C:C,表3[[#This Row],[Port Code]]) -> 45
A4: QINGDAO(青岛) | B4: Qingdao, China | C4: QINGDAO(青岛) | D4: East Asia | E4: North China / Korea / Bohai Bay | F4: CNTAO | G4: MWZ6BhXSNqkOI0ZGa%252FiNmw%253D%253D | H4: MWZ6BhXSNqkOI0ZGa%252FiNmw%253D%253D | I4: =COUNTIF('Port Optimization 001'!C:C,表3[[#This Row],[Port Code]]) -> 73 | J4: =COUNTIF('Port Optimization 365'!C:C,表3[[#This Row],[Port Code]]) -> 64
A5: RIZHAO(日照) | B5: Rizhao, China | C5: RIZHAO(日照) | D5: East Asia | E5: North China / Korea / Bohai Bay | F5: CNRZH | I5: =COUNTIF('Port Optimization 001'!C:C,表3[[#This Row],[Port Code]]) -> 0 | J5: =COUNTIF('Port Optimization 365'!C:C,表3[[#This Row],[Port Code]]) -> 9
A6: LIANYUNGANG(连云港) | B6: Lianyungang, China | C6: LIANYUNGANG(连云港) | D6: East Asia | E6: North China / Korea / Bohai Bay | F6: CNLYG | G6: VKFjVnvddQPZqnPPLjwhPA%253D%253D | H6: VKFjVnvddQPZqnPPLjwhPA%253D%253D | I6: =COUNTIF('Port Optimization 001'!C:C,表3[[#This Row],[Port Code]]) -> 15 | J6: =COUNTIF('Port Optimization 365'!C:C,表3[[#This Row],[Port Code]]) -> 15
A7: TAICANG(太仓) | B7: Taicang, China | C7: TAICANG(太仓) | D7: East Asia | E7: Central China | F7: CNTAC | G7: ZPxtxhVaZJ5ASjrrhzsUew%253D%253D | H7: ZPxtxhVaZJ5ASjrrhzsUew%253D%253D | I7: =COUNTIF('Port Optimization 001'!C:C,表3[[#This Row],[Port Code]]) -> 17 | J7: =COUNTIF('Port Optimization 365'!C:C,表3[[#This Row],[Port Code]]) -> 17
A8: SHANGHAI(上海) | B8: Shanghai, China | C8: SHANGHAI(上海) | D8: East Asia | E8: Central China | F8: CNSHA | G8: lF23NVeEnJTbYGRyP11WaA%253D%253D | H8: lF23NVeEnJTbYGRyP11WaA%253D%253D | I8: =COUNTIF('Port Optimization 001'!C:C,表3[[#This Row],[Port Code]]) -> 73 | J8: =COUNTIF('Port Optimization 365'!C:C,表3[[#This Row],[Port Code]]) -> 73
A9: NINGBO(宁波) | B9: Ningbo, China | C9: NINGBO(宁波) | D9: East Asia | E9: Central China | F9: CNNGB | G9: IWsG%252BSSF6iojvpfUPa6XTQ%253D%253D | H9: IWsG%252BSSF6iojvpfUPa6XTQ%253D%253D | I9: =COUNTIF('Port Optimization 001'!C:C,表3[[#This Row],[Port Code]]) -> 67 | J9: =COUNTIF('Port Optimization 365'!C:C,表3[[#This Row],[Port Code]]) -> 67
A10: FUZHOU(福州) | B10: Fuzhou, China | C10: FUZHOU(福州) | D10: East Asia | E10: Central China | F10: CNFOC | G10: IMQ5I2UzMLVpO9yRTsMYKQ%253D%253D | H10: IMQ5I2UzMLVpO9yRTsMYKQ%253D%253D | I10: =COUNTIF('Port Optimization 001'!C:C,表3[[#This Row],[Port Code]]) -> 0 | J10: =COUNTIF('Port Optimization 365'!C:C,表3[[#This Row],[Port Code]]) -> 0
A11: XIAMEN(厦门) | B11: Xiamen, China | C11: XIAMEN(厦门) | D11: East Asia | E11: Central China | F11: CNXMN | G11: WpPK3zV78YcFQf42f5Zy1Q%253D%253D | H11: WpPK3zV78YcFQf42f5Zy1Q%253D%253D | I11: =COUNTIF('Port Optimization 001'!C:C,表3[[#This Row],[Port Code]]) -> 0 | J11: =COUNTIF('Port Optimization 365'!C:C,表3[[#This Row],[Port Code]]) -> 0
A12: HUANGPU(广州黄埔) | B12: Huangpu, China | C12: HUANGPU(广州黄埔) | D12: East Asia | E12: South China / Pearl River Delta | F12: CNNSA | G12: bdu5TKAjogpTs5Yl4g300w%253D%253D | H12: Nfupi97Q7g5%252BSThhckCGtg%253D%253D | I12: =COUNTIF('Port Optimization 001'!C:C,表3[[#This Row],[Port Code]]) -> 0 | J12: =COUNTIF('Port Optimization 365'!C:C,表3[[#This Row],[Port Code]]) -> 0
A13: NANSHA(广州南沙) | B13: Nansha, China | C13: NANSHA(广州南沙) | D13: East Asia | E13: South China / Pearl River Delta | F13: CNNSA | G13: huvKGL%252B7Fm4wTC3ZfIhHgw%253D%253D | H13: Nfupi97Q7g5%252BSThhckCGtg%253D%253D | I13: =COUNTIF('Port Optimization 001'!C:C,表3[[#This Row],[Port Code]]) -> 0 | J13: =COUNTIF('Port Optimization 365'!C:C,表3[[#This Row],[Port Code]]) -> 0
A14: SHENZHEN(深圳) | B14: Shenzhen, China | C14: SHENZHEN(深圳) | D14: East Asia | E14: South China / Pearl River Delta | F14: CNSZX | G14: jRrNsSuEnc7RSFFSnVIuRQ%253D%253D | H14: jRrNsSuEnc7RSFFSnVIuRQ%253D%253D | I14: =COUNTIF('Port Optimization 001'!C:C,表3[[#This Row],[Port Code]]) -> 0 | J14: =COUNTIF('Port Optimization 365'!C:C,表3[[#This Row],[Port Code]]) -> 0
A15: HONG KONG,CHINA(香港) | B15: Hong Kong, Hong Kong | C15: HONG KONG,CHINA(香港) | D15: East Asia | E15: South China / Pearl River Delta | F15: HKHKG | G15: vMzSod%252BtWz6%252F7wRCS6eQNA%253D%253D | H15: vMzSod%252BtWz6%252F7wRCS6eQNA%253D%253D | I15: =COUNTIF('Port Optimization 001'!C:C,表3[[#This Row],[Port Code]]) -> 0 | J15: =COUNTIF('Port Optimization 365'!C:C,表3[[#This Row],[Port Code]]) -> 0
A16: BANGKOK(曼谷) | B16: Bangkok, Thailand | C16: BANGKOK(曼谷) | D16: Southeast Asia | E16: Thailand | F16: THBKK | G16: OYwFmAgnYZyQLCT3yCs2CA%253D%253D | H16: OYwFmAgnYZyQLCT3yCs2CA%253D%253D | I16: =COUNTIF('Port Optimization 001'!C:C,表3[[#This Row],[Port Code]]) -> 0 | J16: =COUNTIF('Port Optimization 365'!C:C,表3[[#This Row],[Port Code]]) -> 0
A17: LAEM CHABANG(林查班) | B17: Laem Chabang, Thailand | C17: LAEM CHABANG(林查班) | D17: Southeast Asia | E17: Thailand | F17: THLCH | G17: OxmUlXWM%252FAUYd%252FPp1zlwDA%253D%253D | H17: OxmUlXWM%252FAUYd%252FPp1zlwDA%253D%253D | I17: =COUNTIF('Port Optimization 001'!C:C,表3[[#This Row],[Port Code]]) -> 0 | J17: =COUNTIF('Port Optimization 365'!C:C,表3[[#This Row],[Port Code]]) -> 0
... A25: SURABAYA(泗水) | B25: Surabaya, Indonesia | C25: SURABAYA(泗水) | D25: Southeast Asia | E25: Indonesia | F25: IDSUB | G25: HlaejIbbmrtywbtr93rj1w%253D%253D | H25: HlaejIbbmrtywbtr93rj1w%253D%253D | I25: =COUNTIF('Port Optimization 001'!C:C,表3[[#This Row],[Port Code]]) -> 0 | J25: =COUNTIF('Port Optimization 365'!C:C,表3[[#This Row],[Port Code]]) -> 0

Sheet POD
A1: POD.Weiyun | B1: POD.Fleet | C1: Repeat | D1: RANGE | E1: SUB RANGE | F1: Port Code | G1: de | H1: rt | I1: Remark
A2: ABU KIR(阿布基尔) | B2: Abu Qir, Egypt | C2: ABU KIR(阿布基尔) | D2: Mediterranean | E2: SE Med / Libya and Egypt | F2: EGAKI | G2: XFv3OZ1U%252FjcGnp7kGC6M2w%253D%253D | H2: %252B0OYVDebDGU4ZUDCUVe4uQ%253D%253D | I2: 地东
A3: ALEXANDRIA(亚历山大) | B3: Alexandria, Egypt | C3: ALEXANDRIA(亚历山大) | D3: Mediterranean | E3: SE Med / Libya and Egypt | F3: EGALY | G3: 8UZt1A6fmzRdQDqCsc6Xnw%253D%253D | H3: %252B0OYVDebDGU4ZUDCUVe4uQ%253D%253D | I3: 地东
A4: ASHDOD(阿什杜德) | B4: Ashdod, Israel | C4: ASHDOD(阿什杜德) | D4: Mediterranean | E4: NE Med / Adriatic to Levant | F4: ILASH | G4: PclJSlmCYw0M4QT9bT%252BCVw%253D%253D | H4: %252B0OYVDebDGU4ZUDCUVe4uQ%253D%253D | I4: 地东
A5: BEIRUT(贝鲁特) | B5: Beirut, Lebanon | C5: BEIRUT(贝鲁特) | D5: Mediterranean | E5: NE Med / Adriatic to Levant | F5: LBBEY | G5: 8idg1BzLUOfvjKYfU7xSuA%253D%253D | H5: %252B0OYVDebDGU4ZUDCUVe4uQ%253D%253D | I5: 地东
A6: DAMIETTA(达米埃塔) | B6: Damietta, Egypt | C6: DAMIETTA(达米埃塔) | D6: Mediterranean | E6: SE Med / Libya and Egypt | F6: EGDAM | G6: coiwBN9N3PlN5QbECFffOw%253D%253D | H6: %252B0OYVDebDGU4ZUDCUVe4uQ%253D%253D | I6: 地东
A7: DERINCE(代林杰) | B7: Derince, Turkey | C7: DERINCE(代林杰) | D7: Mediterranean | E7: Black Sea / Bosphorus / Marmara | F7: TRDRC | G7: GQUP31MkxSrDx8CJFvrnLA%253D%253D | H7: %252B0OYVDebDGU4ZUDCUVe4uQ%253D%253D | I7: 地东
A8: EL DEKHEILA(亚历山大新港) | B8: El Dekheila, Egypt | C8: EL DEKHEILA(亚历山大新港) | D8: Mediterranean | E8: SE Med / Libya and Egypt | F8: EGEDK | G8: 238evY4dnbosZSyhdCOjNA%253D%253D | H8: %252B0OYVDebDGU4ZUDCUVe4uQ%253D%253D | I8: 地东
A9: HAIFA(海法) | B9: Haifa, Israel | C9: HAIFA(海法) | D9: Mediterranean | E9: NE Med / Adriatic to Levant | F9: ILHFA | G9: HYgAi5Ck8xZ5KeHw3%252BPJ4w%253D%253D | H9: %252B0OYVDebDGU4ZUDCUVe4uQ%253D%253D | I9: 地东
A10: ISKENDERUN(伊斯肯德伦) | B10: Iskenderun, Turkey | C10: ISKENDERUN(伊斯肯德伦) | D10: Mediterranean | E10: NE Med / Adriatic to Levant | F10: TRISK | G10: rRInPlY%252B8%252B%252F9AcpB9ICguQ%253D%253D | H10: %252B0OYVDebDGU4ZUDCUVe4uQ%253D%253D | I10: 地东
A11: IZMIR--ALIAGA(阿利亚加) | B11: Aliaga Izmir, Turkey | C11: IZMIR--ALIAGA(阿利亚加) | D11: Mediterranean | E11: NE Med / Adriatic to Levant | F11: TRALI | G11: PCpzGHJwheo5x9hrTf%252FtNg%253D%253D | H11: %252B0OYVDebDGU4ZUDCUVe4uQ%253D%253D | I11: 地东
A12: IZMIT--YARIMCA(亚勒姆贾) | B12: Yarimca Izmit, Turkey | C12: IZMIT--YARIMCA(亚勒姆贾) | D12: Mediterranean | E12: NE Med / Adriatic to Levant | F12: TRYAR | G12: mE6%252Fp78%252FYp93kfv62oNFWQ%253D%253D | H12: %252B0OYVDebDGU4ZUDCUVe4uQ%253D%253D | I12: 地东
... A285: VIZHINJAM(维津詹姆港) | B285: Vizhinjam, India | C285: VIZHINJAM(维津詹姆港) | D285: Subcontinent, Delta and Sri Lanka | E285: Southern India | F285: INVZJ | G285: 36m0yOFbR2%252B5OGutbHy%252Fbw%253D%253D | H285: ZY9R0ulrUtfklWEEetRGPg%253D%253D | I285: 印巴
G287: de | H287: rt | K287: ap
E288: PHMNN | F288: PHMNL | G288: uYYEeJiaA%252BEFqhyuOo%252FKJg%253D%253D | H288: 1Cobu6af7PO5k9VHay4j%252Bg%253D%253D | K288: KgkQIHXZ%252FEWa2Qb%252Fa4MQtA%253D%253D
E289: PHMNS | F289: PHMNL | G289: %252Bnj61657Gm95NjZ5JyQVuQ%253D%253D | H289: 1Cobu6af7PO5k9VHay4j%252Bg%253D%253D | K289: KgkQIHXZ%252FEWa2Qb%252Fa4MQtA%253D%253D
F290: KRPUS | G290: 8pLSQnjoVis1CMK2AzkKQA%253D%253D | H290: KylH8Pr1ynXpbeNIUggL%252FQ%253D%253D | K290: KgkQIHXZ%252FEWa2Qb%252Fa4MQtA%253D%253D
F291: JPYOK | G291: avzQ%252FxXt%252BKfrK6vIvt59QA%253D%253D | H291: RHiB9uH2veEacXFy%252F4no2w%253D%253D | K291: E414n7wrClEOxW9UQ%252FVHHw%253D%253D
F292: JPHTD | G292: SW6Np5wmifEHSbIFC4MFyg%253D%253D | H292: RHiB9uH2veEacXFy%252F4no2w%253D%253D | K292: E414n7wrClEOxW9UQ%252FVHHw%253D%253D
F293: KRBNP | G293: hl76VvMJR%252Fhqo%252BAR2bQZUw%253D%253D | H293: KylH8Pr1ynXpbeNIUggL%252FQ%253D%253D | K293: E414n7wrClEOxW9UQ%252FVHHw%253D%253D
F294: JPSBS | G294: jVV2E8J20Ak8Jot1PMDX7g%253D%253D | H294: 8qgsJj9tmT8zECAL0Nsagw%253D%253D | K294: E414n7wrClEOxW9UQ%252FVHHw%253D%253D
F295: JPKIJ | G295: %252BwdvuBlBbZiIH8qQ4%252BBPYA%253D%253D | H295: 8qgsJj9tmT8zECAL0Nsagw%253D%253D | K295: E414n7wrClEOxW9UQ%252FVHHw%253D%253D
F296: JPIMI | G296: TRQAybxJZwVsM0rUBE%252Fc2g%253D%253D | H296: 8qgsJj9tmT8zECAL0Nsagw%253D%253D | K296: E414n7wrClEOxW9UQ%252FVHHw%253D%253D
F297: JPOSA | G297: 3agd5gO2ul%252BbrT%252BGjjf0BQ%253D%253D | H297: RHiB9uH2veEacXFy%252F4no2w%253D%253D | K297: E414n7wrClEOxW9UQ%252FVHHw%253D%253D
F298: KRPTK | G298: Tys%252FnB5n00pQrc%252Fq9NrIJQ%253D%253D | H298: KylH8Pr1ynXpbeNIUggL%252FQ%253D%253D | K298: E414n7wrClEOxW9UQ%252FVHHw%253D%253D
F299: RUVYP | G299: KlSWRjDAkivH8De8U2pqPQ%253D%253D | H299: r8vdJELtQ6mqgPEUMkhs6w%253D%253D | K299: E414n7wrClEOxW9UQ%252FVHHw%253D%253D
F300: JPTYO | G300: EYTjpOznR1kHh1upPcXcZQ%253D%253D | H300: RHiB9uH2veEacXFy%252F4no2w%253D%253D | K300: E414n7wrClEOxW9UQ%252FVHHw%253D%253D
F301: KRKWA | G301: rPLnE99TLeh2amlrcypq7A%253D%253D | H301: KylH8Pr1ynXpbeNIUggL%252FQ%253D%253D | K301: E414n7wrClEOxW9UQ%252FVHHw%253D%253D
E302: EGPSE | F302: KRINC | G302: 2UAI1gOlHKk%252FIsLwoS%252Fqdw%253D%253D | H302: KylH8Pr1ynXpbeNIUggL%252FQ%253D%253D | K302: E414n7wrClEOxW9UQ%252FVHHw%253D%253D
E303: EGPSW | F303: EGPSD | G303: dY3UuGWCahDzTcck6Orr3w%253D%253D | H303: %252B0OYVDebDGU4ZUDCUVe4uQ%253D%253D | K303: E414n7wrClEOxW9UQ%252FVHHw%253D%253D
E304: MYWSP | F304: EGPSD | G304: S8f3wUzoiii1L%252Bcw%252BPUmqA%253D%253D | H304: %252B0OYVDebDGU4ZUDCUVe4uQ%253D%253D | K304: KgkQIHXZ%252FEWa2Qb%252Fa4MQtA%253D%253D
E305: MYLPK | F305: MYPKG | G305: 2WJxBRbU754HNWDDwVsKgQ%253D%253D | H305: NFL9cTznAaa4CBynkPs%252B6Q%253D%253D | K305: E414n7wrClEOxW9UQ%252FVHHw%253D%253D
F306: MYPKG | G306: zbLe6PFOMSPvN53Ju2WJ0g%253D%253D | H306: NFL9cTznAaa4CBynkPs%252B6Q%253D%253D | K306: KgkQIHXZ%252FEWa2Qb%252Fa4MQtA%253D%253D
F307: JPMOJ | G307: T9fTu7%252BVgupRHqiIBeaOCg%253D%253D | H307: RHiB9uH2veEacXFy%252F4no2w%253D%253D | K307: E414n7wrClEOxW9UQ%252FVHHw%253D%253D
F308: JPNGO | G308: dbUO0BqxQw4h0hqlxw8ukw%253D%253D | H308: RHiB9uH2veEacXFy%252F4no2w%253D%253D | K308: E414n7wrClEOxW9UQ%252FVHHw%253D%253D
F309: JPTOY | G309: D7QoB%252FZ15idD5nNWMdB6Mg%253D%253D | H309: 8qgsJj9tmT8zECAL0Nsagw%253D%253D | K309: E414n7wrClEOxW9UQ%252FVHHw%253D%253D
F310: KRCHA | G310: kygQwF5lrTdK9bWZyqz0yQ%253D%253D | H310: KylH8Pr1ynXpbeNIUggL%252FQ%253D%253D | K310: E414n7wrClEOxW9UQ%252FVHHw%253D%253D
F311: AUPHE | G311: KGygUm%252FKajBrK1jas6WHlg%253D%253D | H311: o04TRiXb4TdXUQEl8c%252F4bQ%253D%253D | K311: E414n7wrClEOxW9UQ%252FVHHw%253D%253D
F312: PKKHI | G312: 3ez67yisC8fnVI5KVlpklg%253D%253D | H312: ZY9R0ulrUtfklWEEetRGPg%253D%253D | K312: E414n7wrClEOxW9UQ%252FVHHw%253D%253D
F313: JPFKY | G313: pYedXNkKr1mBY5rOJMN3xw%253D%253D | H313: 8qgsJj9tmT8zECAL0Nsagw%253D%253D | K313: E414n7wrClEOxW9UQ%252FVHHw%253D%253D
...

Sheet Port Optimization 001
A1: POL | B1: POD | C1: POL CODE | D1: POD CODE | E1: WEIYUN001 URL | F1: st | G1: de | H1: rg | I1: rt
A2: [DALIAN|CNDLC|中国] | B2: [MANZANILLO MX|MXZLO|墨西哥] | C2: =IF(_xlfn.TEXTBEFORE(_xlfn.TEXTAFTER(A2,"|"),"|")="CNRZH","CNTAO",_xlfn.TEXTBEFORE(_xlfn.TEXTAFTER(A2,"|"),"|")) -> CNDLC | D2: =_xlfn.TEXTBEFORE(_xlfn.TEXTAFTER(B2,"|"),"|") -> MXZLO | E2: ="https://www.weiyun001.com/routePort?st="&Port_Optimization_001[[#This Row],[st]]&"&de="&Port_Optimization_001[[#This Row],[de]]&"&rg="&Port_Optimization_001[[#This Row],[rg]]&"&rt="&Port_Optimization_001[[#This Row],[rt]] -> https://www.weiyun001.com/routePort?st=ngJ9pZF1dUQkTJV1KSwmlw%253D%253D&de=2Hr1qa96pxp8yXraB9fpQw%253D%253D&rg=ngJ9pZF1dUQkTJV1KSwmlw%253D%253D&rt=gR2po4rysa6ynGuDnPrqMA%253D%253D | F2: =VLOOKUP(Port_Optimization_001[[#This Row],[POL CODE]],POL!F:H,2,0) -> ngJ9pZF1dUQkTJV1KSwmlw%253D%253D | G2: =_xlfn.IFNA(VLOOKUP(Port_Optimization_001[[#This Row],[POD CODE]],POD!F:H,2,0),"") -> 2Hr1qa96pxp8yXraB9fpQw%253D%253D | H2: =VLOOKUP(Port_Optimization_001[[#This Row],[POL CODE]],POL!F:H,3,0) -> ngJ9pZF1dUQkTJV1KSwmlw%253D%253D | I2: =_xlfn.IFNA(VLOOKUP(Port_Optimization_001[[#This Row],[POD CODE]],POD!F:H,3,0),"") -> gR2po4rysa6ynGuDnPrqMA%253D%253D
A3: [DALIAN|CNDLC|中国] | B3: [FELIXSTOWE|GBFXT|欧基港] | C3: =IF(_xlfn.TEXTBEFORE(_xlfn.TEXTAFTER(A3,"|"),"|")="CNRZH","CNTAO",_xlfn.TEXTBEFORE(_xlfn.TEXTAFTER(A3,"|"),"|")) -> CNDLC | D3: =_xlfn.TEXTBEFORE(_xlfn.TEXTAFTER(B3,"|"),"|") -> GBFXT | E3: ="https://www.weiyun001.com/routePort?st="&Port_Optimization_001[[#This Row],[st]]&"&de="&Port_Optimization_001[[#This Row],[de]]&"&rg="&Port_Optimization_001[[#This Row],[rg]]&"&rt="&Port_Optimization_001[[#This Row],[rt]] -> https://www.weiyun001.com/routePort?st=ngJ9pZF1dUQkTJV1KSwmlw%253D%253D&de=lyIBtN5jVeYlTjYD7kLYaQ%253D%253D&rg=ngJ9pZF1dUQkTJV1KSwmlw%253D%253D&rt=IV85J0mX0Segto%252FH4Zk5Tg%253D%253D | F3: =VLOOKUP(Port_Optimization_001[[#This Row],[POL CODE]],POL!F:H,2,0) -> ngJ9pZF1dUQkTJV1KSwmlw%253D%253D | G3: =_xlfn.IFNA(VLOOKUP(Port_Optimization_001[[#This Row],[POD CODE]],POD!F:H,2,0),"") -> lyIBtN5jVeYlTjYD7kLYaQ%253D%253D | H3: =VLOOKUP(Port_Optimization_001[[#This Row],[POL CODE]],POL!F:H,3,0) -> ngJ9pZF1dUQkTJV1KSwmlw%253D%253D | I3: =_xlfn.IFNA(VLOOKUP(Port_Optimization_001[[#This Row],[POD CODE]],POD!F:H,3,0),"") -> IV85J0mX0Segto%252FH4Zk5Tg%253D%253D
A4: [DALIAN|CNDLC|中国] | B4: [ROTTERDAM NL|NLRTM|欧基港] | C4: =IF(_xlfn.TEXTBEFORE(_xlfn.TEXTAFTER(A4,"|"),"|")="CNRZH","CNTAO",_xlfn.TEXTBEFORE(_xlfn.TEXTAFTER(A4,"|"),"|")) -> CNDLC | D4: =_xlfn.TEXTBEFORE(_xlfn.TEXTAFTER(B4,"|"),"|") -> NLRTM | E4: ="https://www.weiyun001.com/routePort?st="&Port_Optimization_001[[#This Row],[st]]&"&de="&Port_Optimization_001[[#This Row],[de]]&"&rg="&Port_Optimization_001[[#This Row],[rg]]&"&rt="&Port_Optimization_001[[#This Row],[rt]] -> https://www.weiyun001.com/routePort?st=ngJ9pZF1dUQkTJV1KSwmlw%253D%253D&de=h375AOSlvQCFgmjT%252F5HSqA%253D%253D&rg=ngJ9pZF1dUQkTJV1KSwmlw%253D%253D&rt=IV85J0mX0Segto%252FH4Zk5Tg%253D%253D | F4: =VLOOKUP(Port_Optimization_001[[#This Row],[POL CODE]],POL!F:H,2,0) -> ngJ9pZF1dUQkTJV1KSwmlw%253D%253D | G4: =_xlfn.IFNA(VLOOKUP(Port_Optimization_001[[#This Row],[POD CODE]],POD!F:H,2,0),"") -> h375AOSlvQCFgmjT%252F5HSqA%253D%253D | H4: =VLOOKUP(Port_Optimization_001[[#This Row],[POL CODE]],POL!F:H,3,0) -> ngJ9pZF1dUQkTJV1KSwmlw%253D%253D | I4: =_xlfn.IFNA(VLOOKUP(Port_Optimization_001[[#This Row],[POD CODE]],POD!F:H,3,0),"") -> IV85J0mX0Segto%252FH4Zk5Tg%253D%253D
A5: [DALIAN|CNDLC|中国] | B5: [ISTANBUL|TRIST|黑海] | C5: =IF(_xlfn.TEXTBEFORE(_xlfn.TEXTAFTER(A5,"|"),"|")="CNRZH","CNTAO",_xlfn.TEXTBEFORE(_xlfn.TEXTAFTER(A5,"|"),"|")) -> CNDLC | D5: =_xlfn.TEXTBEFORE(_xlfn.TEXTAFTER(B5,"|"),"|") -> TRIST | E5: ="https://www.weiyun001.com/routePort?st="&Port_Optimization_001[[#This Row],[st]]&"&de="&Port_Optimization_001[[#This Row],[de]]&"&rg="&Port_Optimization_001[[#This Row],[rg]]&"&rt="&Port_Optimization_001[[#This Row],[rt]] -> https://www.weiyun001.com/routePort?st=ngJ9pZF1dUQkTJV1KSwmlw%253D%253D&de=CWZLcxB%252BS05YPBCXZF1ZGg%253D%253D&rg=ngJ9pZF1dUQkTJV1KSwmlw%253D%253D&rt=OWZDyLmv3WGtVP7oMbti8g%253D%253D | F5: =VLOOKUP(Port_Optimization_001[[#This Row],[POL CODE]],POL!F:H,2,0) -> ngJ9pZF1dUQkTJV1KSwmlw%253D%253D | G5: =_xlfn.IFNA(VLOOKUP(Port_Optimization_001[[#This Row],[POD CODE]],POD!F:H,2,0),"") -> CWZLcxB%252BS05YPBCXZF1ZGg%253D%253D | H5: =VLOOKUP(Port_Optimization_001[[#This Row],[POL CODE]],POL!F:H,3,0) -> ngJ9pZF1dUQkTJV1KSwmlw%253D%253D | I5: =_xlfn.IFNA(VLOOKUP(Port_Optimization_001[[#This Row],[POD CODE]],POD!F:H,3,0),"") -> OWZDyLmv3WGtVP7oMbti8g%253D%253D
A6: [DALIAN|CNDLC|中国] | B6: [NHAVA SHEVA|INNSA|印巴] | C6: =IF(_xlfn.TEXTBEFORE(_xlfn.TEXTAFTER(A6,"|"),"|")="CNRZH","CNTAO",_xlfn.TEXTBEFORE(_xlfn.TEXTAFTER(A6,"|"),"|")) -> CNDLC | D6: =_xlfn.TEXTBEFORE(_xlfn.TEXTAFTER(B6,"|"),"|") -> INNSA | E6: ="https://www.weiyun001.com/routePort?st="&Port_Optimization_001[[#This Row],[st]]&"&de="&Port_Optimization_001[[#This Row],[de]]&"&rg="&Port_Optimization_001[[#This Row],[rg]]&"&rt="&Port_Optimization_001[[#This Row],[rt]] -> https://www.weiyun001.com/routePort?st=ngJ9pZF1dUQkTJV1KSwmlw%253D%253D&de=jD0OvY0B6WYFRxQO7kBFtg%253D%253D&rg=ngJ9pZF1dUQkTJV1KSwmlw%253D%253D&rt=ZY9R0ulrUtfklWEEetRGPg%253D%253D | F6: =VLOOKUP(Port_Optimization_001[[#This Row],[POL CODE]],POL!F:H,2,0) -> ngJ9pZF1dUQkTJV1KSwmlw%253D%253D | G6: =_xlfn.IFNA(VLOOKUP(Port_Optimization_001[[#This Row],[POD CODE]],POD!F:H,2,0),"") -> jD0OvY0B6WYFRxQO7kBFtg%253D%253D | H6: =VLOOKUP(Port_Optimization_001[[#This Row],[POL CODE]],POL!F:H,3,0) -> ngJ9pZF1dUQkTJV1KSwmlw%253D%253D | I6: =_xlfn.IFNA(VLOOKUP(Port_Optimization_001[[#This Row],[POD CODE]],POD!F:H,3,0),"") -> ZY9R0ulrUtfklWEEetRGPg%253D%253D
A7: [DALIAN|CNDLC|中国] | B7: [JEBEL ALI DUBAI|AEJEA|中东] | C7: =IF(_xlfn.TEXTBEFORE(_xlfn.TEXTAFTER(A7,"|"),"|")="CNRZH","CNTAO",_xlfn.TEXTBEFORE(_xlfn.TEXTAFTER(A7,"|"),"|")) -> CNDLC | D7: =_xlfn.TEXTBEFORE(_xlfn.TEXTAFTER(B7,"|"),"|") -> AEJEA | E7: ="https://www.weiyun001.com/routePort?st="&Port_Optimization_001[[#This Row],[st]]&"&de="&Port_Optimization_001[[#This Row],[de]]&"&rg="&Port_Optimization_001[[#This Row],[rg]]&"&rt="&Port_Optimization_001[[#This Row],[rt]] -> https://www.weiyun001.com/routePort?st=ngJ9pZF1dUQkTJV1KSwmlw%253D%253D&de=SbjTwb99PCeDQHDeZwEvvA%253D%253D&rg=ngJ9pZF1dUQkTJV1KSwmlw%253D%253D&rt=nIJ3Uyv%252Bm7qB2PS5QvkN1A%253D%253D | F7: =VLOOKUP(Port_Optimization_001[[#This Row],[POL CODE]],POL!F:H,2,0) -> ngJ9pZF1dUQkTJV1KSwmlw%253D%253D | G7: =_xlfn.IFNA(VLOOKUP(Port_Optimization_001[[#This Row],[POD CODE]],POD!F:H,2,0),"") -> SbjTwb99PCeDQHDeZwEvvA%253D%253D | H7: =VLOOKUP(Port_Optimization_001[[#This Row],[POL CODE]],POL!F:H,3,0) -> ngJ9pZF1dUQkTJV1KSwmlw%253D%253D | I7: =_xlfn.IFNA(VLOOKUP(Port_Optimization_001[[#This Row],[POD CODE]],POD!F:H,3,0),"") -> nIJ3Uyv%252Bm7qB2PS5QvkN1A%253D%253D
A8: [DALIAN|CNDLC|中国] | B8: [HOCHIMINH|VNSGN|新马越泰] | C8: =IF(_xlfn.TEXTBEFORE(_xlfn.TEXTAFTER(A8,"|"),"|")="CNRZH","CNTAO",_xlfn.TEXTBEFORE(_xlfn.TEXTAFTER(A8,"|"),"|")) -> CNDLC | D8: =_xlfn.TEXTBEFORE(_xlfn.TEXTAFTER(B8,"|"),"|") -> VNSGN | E8: ="https://www.weiyun001.com/routePort?st="&Port_Optimization_001[[#This Row],[st]]&"&de="&Port_Optimization_001[[#This Row],[de]]&"&rg="&Port_Optimization_001[[#This Row],[rg]]&"&rt="&Port_Optimization_001[[#This Row],[rt]] -> https://www.weiyun001.com/routePort?st=ngJ9pZF1dUQkTJV1KSwmlw%253D%253D&de=CVigZ03WwsIi3M4cUzX1IA%253D%253D&rg=ngJ9pZF1dUQkTJV1KSwmlw%253D%253D&rt=NFL9cTznAaa4CBynkPs%252B6Q%253D%253D | F8: =VLOOKUP(Port_Optimization_001[[#This Row],[POL CODE]],POL!F:H,2,0) -> ngJ9pZF1dUQkTJV1KSwmlw%253D%253D | G8: =_xlfn.IFNA(VLOOKUP(Port_Optimization_001[[#This Row],[POD CODE]],POD!F:H,2,0),"") -> CVigZ03WwsIi3M4cUzX1IA%253D%253D | H8: =VLOOKUP(Port_Optimization_001[[#This Row],[POL CODE]],POL!F:H,3,0) -> ngJ9pZF1dUQkTJV1KSwmlw%253D%253D | I8: =_xlfn.IFNA(VLOOKUP(Port_Optimization_001[[#This Row],[POD CODE]],POD!F:H,3,0),"") -> NFL9cTznAaa4CBynkPs%252B6Q%253D%253D
A9: [DALIAN|CNDLC|中国] | B9: [MANILA|PHMNL|印尼 菲律宾] | C9: =IF(_xlfn.TEXTBEFORE(_xlfn.TEXTAFTER(A9,"|"),"|")="CNRZH","CNTAO",_xlfn.TEXTBEFORE(_xlfn.TEXTAFTER(A9,"|"),"|")) -> CNDLC | D9: =_xlfn.TEXTBEFORE(_xlfn.TEXTAFTER(B9,"|"),"|") -> PHMNL | E9: ="https://www.weiyun001.com/routePort?st="&Port_Optimization_001[[#This Row],[st]]&"&de="&Port_Optimization_001[[#This Row],[de]]&"&rg="&Port_Optimization_001[[#This Row],[rg]]&"&rt="&Port_Optimization_001[[#This Row],[rt]] -> https://www.weiyun001.com/routePort?st=ngJ9pZF1dUQkTJV1KSwmlw%253D%253D&de=uYYEeJiaA%252BEFqhyuOo%252FKJg%253D%253D&rg=ngJ9pZF1dUQkTJV1KSwmlw%253D%253D&rt=1Cobu6af7PO5k9VHay4j%252Bg%253D%253D | F9: =VLOOKUP(Port_Optimization_001[[#This Row],[POL CODE]],POL!F:H,2,0) -> ngJ9pZF1dUQkTJV1KSwmlw%253D%253D | G9: =_xlfn.IFNA(VLOOKUP(Port_Optimization_001[[#This Row],[POD CODE]],POD!F:H,2,0),"") -> uYYEeJiaA%252BEFqhyuOo%252FKJg%253D%253D | H9: =VLOOKUP(Port_Optimization_001[[#This Row],[POL CODE]],POL!F:H,3,0) -> ngJ9pZF1dUQkTJV1KSwmlw%253D%253D | I9: =_xlfn.IFNA(VLOOKUP(Port_Optimization_001[[#This Row],[POD CODE]],POD!F:H,3,0),"") -> 1Cobu6af7PO5k9VHay4j%252Bg%253D%253D
A10: [DALIAN|CNDLC|中国] | B10: [JAKARTA|IDJKT|印尼 菲律宾] | C10: =IF(_xlfn.TEXTBEFORE(_xlfn.TEXTAFTER(A10,"|"),"|")="CNRZH","CNTAO",_xlfn.TEXTBEFORE(_xlfn.TEXTAFTER(A10,"|"),"|")) -> CNDLC | D10: =_xlfn.TEXTBEFORE(_xlfn.TEXTAFTER(B10,"|"),"|") -> IDJKT | E10: ="https://www.weiyun001.com/routePort?st="&Port_Optimization_001[[#This Row],[st]]&"&de="&Port_Optimization_001[[#This Row],[de]]&"&rg="&Port_Optimization_001[[#This Row],[rg]]&"&rt="&Port_Optimization_001[[#This Row],[rt]] -> https://www.weiyun001.com/routePort?st=ngJ9pZF1dUQkTJV1KSwmlw%253D%253D&de=ffFYXkaqrPSmqfQq9H1AYQ%253D%253D&rg=ngJ9pZF1dUQkTJV1KSwmlw%253D%253D&rt=1Cobu6af7PO5k9VHay4j%252Bg%253D%253D | F10: =VLOOKUP(Port_Optimization_001[[#This Row],[POL CODE]],POL!F:H,2,0) -> ngJ9pZF1dUQkTJV1KSwmlw%253D%253D | G10: =_xlfn.IFNA(VLOOKUP(Port_Optimization_001[[#This Row],[POD CODE]],POD!F:H,2,0),"") -> ffFYXkaqrPSmqfQq9H1AYQ%253D%253D | H10: =VLOOKUP(Port_Optimization_001[[#This Row],[POL CODE]],POL!F:H,3,0) -> ngJ9pZF1dUQkTJV1KSwmlw%253D%253D | I10: =_xlfn.IFNA(VLOOKUP(Port_Optimization_001[[#This Row],[POD CODE]],POD!F:H,3,0),"") -> 1Cobu6af7PO5k9VHay4j%252Bg%253D%253D
A11: [DALIAN|CNDLC|中国] | B11: [HAIPHONG|VNHPH|新马越泰] | C11: =IF(_xlfn.TEXTBEFORE(_xlfn.TEXTAFTER(A11,"|"),"|")="CNRZH","CNTAO",_xlfn.TEXTBEFORE(_xlfn.TEXTAFTER(A11,"|"),"|")) -> CNDLC | D11: =_xlfn.TEXTBEFORE(_xlfn.TEXTAFTER(B11,"|"),"|") -> VNHPH | E11: ="https://www.weiyun001.com/routePort?st="&Port_Optimization_001[[#This Row],[st]]&"&de="&Port_Optimization_001[[#This Row],[de]]&"&rg="&Port_Optimization_001[[#This Row],[rg]]&"&rt="&Port_Optimization_001[[#This Row],[rt]] -> https://www.weiyun001.com/routePort?st=ngJ9pZF1dUQkTJV1KSwmlw%253D%253D&de=fJ71EUPe75vnyZvJ9cGHxg%253D%253D&rg=ngJ9pZF1dUQkTJV1KSwmlw%253D%253D&rt=NFL9cTznAaa4CBynkPs%252B6Q%253D%253D | F11: =VLOOKUP(Port_Optimization_001[[#This Row],[POL CODE]],POL!F:H,2,0) -> ngJ9pZF1dUQkTJV1KSwmlw%253D%253D | G11: =_xlfn.IFNA(VLOOKUP(Port_Optimization_001[[#This Row],[POD CODE]],POD!F:H,2,0),"") -> fJ71EUPe75vnyZvJ9cGHxg%253D%253D | H11: =VLOOKUP(Port_Optimization_001[[#This Row],[POL CODE]],POL!F:H,3,0) -> ngJ9pZF1dUQkTJV1KSwmlw%253D%253D | I11: =_xlfn.IFNA(VLOOKUP(Port_Optimization_001[[#This Row],[POD CODE]],POD!F:H,3,0),"") -> NFL9cTznAaa4CBynkPs%252B6Q%253D%253D
A12: [DALIAN|CNDLC|中国] | B12: [LAEM CHABANG|THLCH|新马越泰] | C12: =IF(_xlfn.TEXTBEFORE(_xlfn.TEXTAFTER(A12,"|"),"|")="CNRZH","CNTAO",_xlfn.TEXTBEFORE(_xlfn.TEXTAFTER(A12,"|"),"|")) -> CNDLC | D12: =_xlfn.TEXTBEFORE(_xlfn.TEXTAFTER(B12,"|"),"|") -> THLCH | E12: ="https://www.weiyun001.com/routePort?st="&Port_Optimization_001[[#This Row],[st]]&"&de="&Port_Optimization_001[[#This Row],[de]]&"&rg="&Port_Optimization_001[[#This Row],[rg]]&"&rt="&Port_Optimization_001[[#This Row],[rt]] -> https://www.weiyun001.com/routePort?st=ngJ9pZF1dUQkTJV1KSwmlw%253D%253D&de=OxmUlXWM%252FAUYd%252FPp1zlwDA%253D%253D&rg=ngJ9pZF1dUQkTJV1KSwmlw%253D%253D&rt=NFL9cTznAaa4CBynkPs%252B6Q%253D%253D | F12: =VLOOKUP(Port_Optimization_001[[#This Row],[POL CODE]],POL!F:H,2,0) -> ngJ9pZF1dUQkTJV1KSwmlw%253D%253D | G12: =_xlfn.IFNA(VLOOKUP(Port_Optimization_001[[#This Row],[POD CODE]],POD!F:H,2,0),"") -> OxmUlXWM%252FAUYd%252FPp1zlwDA%253D%253D | H12: =VLOOKUP(Port_Optimization_001[[#This Row],[POL CODE]],POL!F:H,3,0) -> ngJ9pZF1dUQkTJV1KSwmlw%253D%253D | I12: =_xlfn.IFNA(VLOOKUP(Port_Optimization_001[[#This Row],[POD CODE]],POD!F:H,3,0),"") -> NFL9cTznAaa4CBynkPs%252B6Q%253D%253D
A13: [DALIAN|CNDLC|中国] | B13: [TANJUNG PELEPAS|MYTPP|新马越泰] | C13: =IF(_xlfn.TEXTBEFORE(_xlfn.TEXTAFTER(A13,"|"),"|")="CNRZH","CNTAO",_xlfn.TEXTBEFORE(_xlfn.TEXTAFTER(A13,"|"),"|")) -> CNDLC | D13: =_xlfn.TEXTBEFORE(_xlfn.TEXTAFTER(B13,"|"),"|") -> MYTPP | E13: ="https://www.weiyun001.com/routePort?st="&Port_Optimization_001[[#This Row],[st]]&"&de="&Port_Optimization_001[[#This Row],[de]]&"&rg="&Port_Optimization_001[[#This Row],[rg]]&"&rt="&Port_Optimization_001[[#This Row],[rt]] -> https://www.weiyun001.com/routePort?st=ngJ9pZF1dUQkTJV1KSwmlw%253D%253D&de=Zfdwz371n2fV4bpx64twzQ%253D%253D&rg=ngJ9pZF1dUQkTJV1KSwmlw%253D%253D&rt=NFL9cTznAaa4CBynkPs%252B6Q%253D%253D | F13: =VLOOKUP(Port_Optimization_001[[#This Row],[POL CODE]],POL!F:H,2,0) -> ngJ9pZF1dUQkTJV1KSwmlw%253D%253D | G13: =_xlfn.IFNA(VLOOKUP(Port_Optimization_001[[#This Row],[POD CODE]],POD!F:H,2,0),"") -> Zfdwz371n2fV4bpx64twzQ%253D%253D | H13: =VLOOKUP(Port_Optimization_001[[#This Row],[POL CODE]],POL!F:H,3,0) -> ngJ9pZF1dUQkTJV1KSwmlw%253D%253D | I13: =_xlfn.IFNA(VLOOKUP(Port_Optimization_001[[#This Row],[POD CODE]],POD!F:H,3,0),"") -> NFL9cTznAaa4CBynkPs%252B6Q%253D%253D
... A320: [TIANJIN|CNTXG|中国] | B320: [PYEONGTAEK|KRPTK|韩国] | C320: =IF(_xlfn.TEXTBEFORE(_xlfn.TEXTAFTER(A320,"|"),"|")="CNRZH","CNTAO",_xlfn.TEXTBEFORE(_xlfn.TEXTAFTER(A320,"|"),"|")) -> CNTXG | D320: =_xlfn.TEXTBEFORE(_xlfn.TEXTAFTER(B320,"|"),"|") -> KRPTK | E320: ="https://www.weiyun001.com/routePort?st="&Port_Optimization_001[[#This Row],[st]]&"&de="&Port_Optimization_001[[#This Row],[de]]&"&rg="&Port_Optimization_001[[#This Row],[rg]]&"&rt="&Port_Optimization_001[[#This Row],[rt]] -> https://www.weiyun001.com/routePort?st=9vlbrGDCGWoPotdwnakh4g%253D%253D&de=Tys%252FnB5n00pQrc%252Fq9NrIJQ%253D%253D&rg=9vlbrGDCGWoPotdwnakh4g%253D%253D&rt=KylH8Pr1ynXpbeNIUggL%252FQ%253D%253D | F320: =VLOOKUP(Port_Optimization_001[[#This Row],[POL CODE]],POL!F:H,2,0) -> 9vlbrGDCGWoPotdwnakh4g%253D%253D | G320: =_xlfn.IFNA(VLOOKUP(Port_Optimization_001[[#This Row],[POD CODE]],POD!F:H,2,0),"") -> Tys%252FnB5n00pQrc%252Fq9NrIJQ%253D%253D | H320: =VLOOKUP(Port_Optimization_001[[#This Row],[POL CODE]],POL!F:H,3,0) -> 9vlbrGDCGWoPotdwnakh4g%253D%253D | I320: =_xlfn.IFNA(VLOOKUP(Port_Optimization_001[[#This Row],[POD CODE]],POD!F:H,3,0),"") -> KylH8Pr1ynXpbeNIUggL%252FQ%253D%253D
A322: [DALIAN|CNDLC|中国] | B322: [DONG NAI|VNDNA|新马越泰] | C322: =IF(_xlfn.TEXTBEFORE(_xlfn.TEXTAFTER(A322,"|"),"|")="CNRZH","CNTAO",_xlfn.TEXTBEFORE(_xlfn.TEXTAFTER(A322,"|"),"|")) -> CNDLC | D322: =_xlfn.TEXTBEFORE(_xlfn.TEXTAFTER(B322,"|"),"|") -> VNDNA | E322: ="https://www.weiyun001.com/routePort?st="&F322&"&de="&G322&"&rg="&H322&"&rt="&I322 -> https://www.weiyun001.com/routePort?st=ngJ9pZF1dUQkTJV1KSwmlw%253D%253D&de=rTBDz0ZlCGUJL5mkze3Rqw%253D%253D&rg=ngJ9pZF1dUQkTJV1KSwmlw%253D%253D&rt=NFL9cTznAaa4CBynkPs%252B6Q%253D%253D | F322: =VLOOKUP(C322,POL!F:H,2,0) -> ngJ9pZF1dUQkTJV1KSwmlw%253D%253D | G322: =_xlfn.IFNA(VLOOKUP(D322,POD!F:H,2,0),"") -> rTBDz0ZlCGUJL5mkze3Rqw%253D%253D | H322: =VLOOKUP(C322,POL!F:H,3,0) -> ngJ9pZF1dUQkTJV1KSwmlw%253D%253D | I322: =_xlfn.IFNA(VLOOKUP(D322,POD!F:H,3,0),"") -> NFL9cTznAaa4CBynkPs%252B6Q%253D%253D
A323: [TIANJIN|CNTXG|中国] | B323: [DONG NAI|VNDNA|新马越泰] | C323: =IF(_xlfn.TEXTBEFORE(_xlfn.TEXTAFTER(A323,"|"),"|")="CNRZH","CNTAO",_xlfn.TEXTBEFORE(_xlfn.TEXTAFTER(A323,"|"),"|")) -> CNTXG | D323: =_xlfn.TEXTBEFORE(_xlfn.TEXTAFTER(B323,"|"),"|") -> VNDNA | E323: ="https://www.weiyun001.com/routePort?st="&F323&"&de="&G323&"&rg="&H323&"&rt="&I323 -> https://www.weiyun001.com/routePort?st=9vlbrGDCGWoPotdwnakh4g%253D%253D&de=rTBDz0ZlCGUJL5mkze3Rqw%253D%253D&rg=9vlbrGDCGWoPotdwnakh4g%253D%253D&rt=NFL9cTznAaa4CBynkPs%252B6Q%253D%253D | F323: =VLOOKUP(C323,POL!F:H,2,0) -> 9vlbrGDCGWoPotdwnakh4g%253D%253D | G323: =_xlfn.IFNA(VLOOKUP(D323,POD!F:H,2,0),"") -> rTBDz0ZlCGUJL5mkze3Rqw%253D%253D | H323: =VLOOKUP(C323,POL!F:H,3,0) -> 9vlbrGDCGWoPotdwnakh4g%253D%253D | I323: =_xlfn.IFNA(VLOOKUP(D323,POD!F:H,3,0),"") -> NFL9cTznAaa4CBynkPs%252B6Q%253D%253D
A324: [QINGDAO SHANDONG|CNTAO|中国] | B324: [DONG NAI|VNDNA|新马越泰] | C324: =IF(_xlfn.TEXTBEFORE(_xlfn.TEXTAFTER(A324,"|"),"|")="CNRZH","CNTAO",_xlfn.TEXTBEFORE(_xlfn.TEXTAFTER(A324,"|"),"|")) -> CNTAO | D324: =_xlfn.TEXTBEFORE(_xlfn.TEXTAFTER(B324,"|"),"|") -> VNDNA | E324: ="https://www.weiyun001.com/routePort?st="&F324&"&de="&G324&"&rg="&H324&"&rt="&I324 -> https://www.weiyun001.com/routePort?st=MWZ6BhXSNqkOI0ZGa%252FiNmw%253D%253D&de=rTBDz0ZlCGUJL5mkze3Rqw%253D%253D&rg=MWZ6BhXSNqkOI0ZGa%252FiNmw%253D%253D&rt=NFL9cTznAaa4CBynkPs%252B6Q%253D%253D | F324: =VLOOKUP(C324,POL!F:H,2,0) -> MWZ6BhXSNqkOI0ZGa%252FiNmw%253D%253D | G324: =_xlfn.IFNA(VLOOKUP(D324,POD!F:H,2,0),"") -> rTBDz0ZlCGUJL5mkze3Rqw%253D%253D | H324: =VLOOKUP(C324,POL!F:H,3,0) -> MWZ6BhXSNqkOI0ZGa%252FiNmw%253D%253D | I324: =_xlfn.IFNA(VLOOKUP(D324,POD!F:H,3,0),"") -> NFL9cTznAaa4CBynkPs%252B6Q%253D%253D

Sheet Port Optimization 365
A1: POL | B1: POD | C1: POL CODE | D1: POD CODE | E1: HANGYUN365 URL
A2: [DALIAN|CNDLC|中国] | B2: [MANZANILLO MX|MXZLO|墨西哥] | C2: =_xlfn.TEXTBEFORE(_xlfn.TEXTAFTER(A2,"|"),"|") -> CNDLC | D2: =_xlfn.TEXTBEFORE(_xlfn.TEXTAFTER(B2,"|"),"|") -> MXZLO | E2: ="https://www.hangyun365.com/Shipping?pol_code="&Port_Optimization_365[[#This Row],[POL CODE]]&"&pod_code="&Port_Optimization_365[[#This Row],[POD CODE]] -> https://www.hangyun365.com/Shipping?pol_code=CNDLC&pod_code=MXZLO
A3: [DALIAN|CNDLC|中国] | B3: [FELIXSTOWE|GBFXT|欧基港] | C3: =_xlfn.TEXTBEFORE(_xlfn.TEXTAFTER(A3,"|"),"|") -> CNDLC | D3: =_xlfn.TEXTBEFORE(_xlfn.TEXTAFTER(B3,"|"),"|") -> GBFXT | E3: ="https://www.hangyun365.com/Shipping?pol_code="&Port_Optimization_365[[#This Row],[POL CODE]]&"&pod_code="&Port_Optimization_365[[#This Row],[POD CODE]] -> https://www.hangyun365.com/Shipping?pol_code=CNDLC&pod_code=GBFXT
A4: [DALIAN|CNDLC|中国] | B4: [ROTTERDAM NL|NLRTM|欧基港] | C4: =_xlfn.TEXTBEFORE(_xlfn.TEXTAFTER(A4,"|"),"|") -> CNDLC | D4: =_xlfn.TEXTBEFORE(_xlfn.TEXTAFTER(B4,"|"),"|") -> NLRTM | E4: ="https://www.hangyun365.com/Shipping?pol_code="&Port_Optimization_365[[#This Row],[POL CODE]]&"&pod_code="&Port_Optimization_365[[#This Row],[POD CODE]] -> https://www.hangyun365.com/Shipping?pol_code=CNDLC&pod_code=NLRTM
A5: [DALIAN|CNDLC|中国] | B5: [ISTANBUL|TRIST|黑海] | C5: =_xlfn.TEXTBEFORE(_xlfn.TEXTAFTER(A5,"|"),"|") -> CNDLC | D5: =_xlfn.TEXTBEFORE(_xlfn.TEXTAFTER(B5,"|"),"|") -> TRIST | E5: ="https://www.hangyun365.com/Shipping?pol_code="&Port_Optimization_365[[#This Row],[POL CODE]]&"&pod_code="&Port_Optimization_365[[#This Row],[POD CODE]] -> https://www.hangyun365.com/Shipping?pol_code=CNDLC&pod_code=TRIST
A6: [DALIAN|CNDLC|中国] | B6: [NHAVA SHEVA|INNSA|印巴] | C6: =_xlfn.TEXTBEFORE(_xlfn.TEXTAFTER(A6,"|"),"|") -> CNDLC | D6: =_xlfn.TEXTBEFORE(_xlfn.TEXTAFTER(B6,"|"),"|") -> INNSA | E6: ="https://www.hangyun365.com/Shipping?pol_code="&Port_Optimization_365[[#This Row],[POL CODE]]&"&pod_code="&Port_Optimization_365[[#This Row],[POD CODE]] -> https://www.hangyun365.com/Shipping?pol_code=CNDLC&pod_code=INNSA
A7: [DALIAN|CNDLC|中国] | B7: [JEBEL ALI DUBAI|AEJEA|中东] | C7: =_xlfn.TEXTBEFORE(_xlfn.TEXTAFTER(A7,"|"),"|") -> CNDLC | D7: =_xlfn.TEXTBEFORE(_xlfn.TEXTAFTER(B7,"|"),"|") -> AEJEA | E7: ="https://www.hangyun365.com/Shipping?pol_code="&Port_Optimization_365[[#This Row],[POL CODE]]&"&pod_code="&Port_Optimization_365[[#This Row],[POD CODE]] -> https://www.hangyun365.com/Shipping?pol_code=CNDLC&pod_code=AEJEA
A8: [DALIAN|CNDLC|中国] | B8: [HOCHIMINH|VNSGN|新马越泰] | C8: =_xlfn.TEXTBEFORE(_xlfn.TEXTAFTER(A8,"|"),"|") -> CNDLC | D8: =_xlfn.TEXTBEFORE(_xlfn.TEXTAFTER(B8,"|"),"|") -> VNSGN | E8: ="https://www.hangyun365.com/Shipping?pol_code="&Port_Optimization_365[[#This Row],[POL CODE]]&"&pod_code="&Port_Optimization_365[[#This Row],[POD CODE]] -> https://www.hangyun365.com/Shipping?pol_code=CNDLC&pod_code=VNSGN
A9: [DALIAN|CNDLC|中国] | B9: [MANILA|PHMNL|印尼 菲律宾] | C9: =_xlfn.TEXTBEFORE(_xlfn.TEXTAFTER(A9,"|"),"|") -> CNDLC | D9: =_xlfn.TEXTBEFORE(_xlfn.TEXTAFTER(B9,"|"),"|") -> PHMNL | E9: ="https://www.hangyun365.com/Shipping?pol_code="&Port_Optimization_365[[#This Row],[POL CODE]]&"&pod_code="&Port_Optimization_365[[#This Row],[POD CODE]] -> https://www.hangyun365.com/Shipping?pol_code=CNDLC&pod_code=PHMNL
A10: [DALIAN|CNDLC|中国] | B10: [JAKARTA|IDJKT|印尼 菲律宾] | C10: =_xlfn.TEXTBEFORE(_xlfn.TEXTAFTER(A10,"|"),"|") -> CNDLC | D10: =_xlfn.TEXTBEFORE(_xlfn.TEXTAFTER(B10,"|"),"|") -> IDJKT | E10: ="https://www.hangyun365.com/Shipping?pol_code="&Port_Optimization_365[[#This Row],[POL CODE]]&"&pod_code="&Port_Optimization_365[[#This Row],[POD CODE]] -> https://www.hangyun365.com/Shipping?pol_code=CNDLC&pod_code=IDJKT
A11: [DALIAN|CNDLC|中国] | B11: [HAIPHONG|VNHPH|新马越泰] | C11: =_xlfn.TEXTBEFORE(_xlfn.TEXTAFTER(A11,"|"),"|") -> CNDLC | D11: =_xlfn.TEXTBEFORE(_xlfn.TEXTAFTER(B11,"|"),"|") -> VNHPH | E11: ="https://www.hangyun365.com/Shipping?pol_code="&Port_Optimization_365[[#This Row],[POL CODE]]&"&pod_code="&Port_Optimization_365[[#This Row],[POD CODE]] -> https://www.hangyun365.com/Shipping?pol_code=CNDLC&pod_code=VNHPH
A12: [DALIAN|CNDLC|中国] | B12: [LAEM CHABANG|THLCH|新马越泰] | C12: =_xlfn.TEXTBEFORE(_xlfn.TEXTAFTER(A12,"|"),"|") -> CNDLC | D12: =_xlfn.TEXTBEFORE(_xlfn.TEXTAFTER(B12,"|"),"|") -> THLCH | E12: ="https://www.hangyun365.com/Shipping?pol_code="&Port_Optimization_365[[#This Row],[POL CODE]]&"&pod_code="&Port_Optimization_365[[#This Row],[POD CODE]] -> https://www.hangyun365.com/Shipping?pol_code=CNDLC&pod_code=THLCH
A13: [DALIAN|CNDLC|中国] | B13: [TANJUNG PELEPAS|MYTPP|新马越泰] | C13: =_xlfn.TEXTBEFORE(_xlfn.TEXTAFTER(A13,"|"),"|") -> CNDLC | D13: =_xlfn.TEXTBEFORE(_xlfn.TEXTAFTER(B13,"|"),"|") -> MYTPP | E13: ="https://www.hangyun365.com/Shipping?pol_code="&Port_Optimization_365[[#This Row],[POL CODE]]&"&pod_code="&Port_Optimization_365[[#This Row],[POD CODE]] -> https://www.hangyun365.com/Shipping?pol_code=CNDLC&pod_code=MYTPP
... A320: [TIANJIN|CNTXG|中国] | B320: [PYEONGTAEK|KRPTK|韩国] | C320: =_xlfn.TEXTBEFORE(_xlfn.TEXTAFTER(A320,"|"),"|") -> CNTXG | D320: =_xlfn.TEXTBEFORE(_xlfn.TEXTAFTER(B320,"|"),"|") -> KRPTK | E320: ="https://www.hangyun365.com/Shipping?pol_code="&Port_Optimization_365[[#This Row],[POL CODE]]&"&pod_code="&Port_Optimization_365[[#This Row],[POD CODE]] -> https://www.hangyun365.com/Shipping?pol_code=CNTXG&pod_code=KRPTK
A322: [DALIAN|CNDLC|中国] | B322: [DONG NAI|VNDNA|新马越泰] | C322: =_xlfn.TEXTBEFORE(_xlfn.TEXTAFTER(A322,"|"),"|") -> CNDLC | D322: =_xlfn.TEXTBEFORE(_xlfn.TEXTAFTER(B322,"|"),"|") -> VNDNA | E322: ="https://www.hangyun365.com/Shipping?pol_code="&C322&"&pod_code="&D322 -> https://www.hangyun365.com/Shipping?pol_code=CNDLC&pod_code=VNDNA
A323: [TIANJIN|CNTXG|中国] | B323: [DONG NAI|VNDNA|新马越泰] | C323: =_xlfn.TEXTBEFORE(_xlfn.TEXTAFTER(A323,"|"),"|") -> CNTXG | D323: =_xlfn.TEXTBEFORE(_xlfn.TEXTAFTER(B323,"|"),"|") -> VNDNA | E323: ="https://www.hangyun365.com/Shipping?pol_code="&C323&"&pod_code="&D323 -> https://www.hangyun365.com/Shipping?pol_code=CNTXG&pod_code=VNDNA
A324: [QINGDAO SHANDONG|CNTAO|中国] | B324: [DONG NAI|VNDNA|新马越泰] | C324: =_xlfn.TEXTBEFORE(_xlfn.TEXTAFTER(A324,"|"),"|") -> CNTAO | D324: =_xlfn.TEXTBEFORE(_xlfn.TEXTAFTER(B324,"|"),"|") -> VNDNA | E324: ="https://www.hangyun365.com/Shipping?pol_code="&C324&"&pod_code="&D324 -> https://www.hangyun365.com/Shipping?pol_code=CNTAO&pod_code=VNDNA
